Workbook

Sheet 0_Instructions
B1: Module 1 Assessment — Excel & Data Fundamentals
B2: Wits Coding & Digital Innovation Society · Academic Year 2026
B4: OVERVIEW
B5: This workbook is your assessment for Module 1. You will work with 12 months of real JSE (Johannesburg Stock Exchange) trading data across five blue-chip South African companies. Complete all tasks in the order listed below. Submit the completed workbook via your GitHub repository.
B7: DATASET
B8: Sheet: 1_RawData — 1 460 rows of daily trading data, January–December 2025
B9: Columns: A=Date | B=Ticker | C=Company | D=Sector | E=Open(R) | F=High(R) | G=Low(R) | H=Close(R) | I=Volume | J=Mkt Cap(R)
B11: TASK 1 — Understand the Dataset [10 marks]
B12: 1.1 Go to sheet 1_RawData. In the yellow answer cell (K2), state how many rows of data exist (excluding the header).
B13: 1.2 In cell K3, write the formula that counts how many unique tickers appear in column B.
B14: 1.3 In cell K4, identify and type the date range of the dataset (first date to last date).
B15: 1.4 In cells K6:K10, manually list one data quality issue you notice per row. (Hint: look at data types, formatting, inconsistencies in column D Sector.)
... B58: 4. Your README.md should include a brief note on what you built and one finding from your analysis.

Sheet 1_RawData
A1: Date | B1: Ticker | C1: Company | D1: Sector | E1: Open (R) | F1: High (R) | G1: Low (R) | H1: Close (R) | I1: Volume | J1: Mkt Cap (R) | K1: Task 1 Answers
A2: 45659 | B2: NPN | C2: Naspers | D2: Technology | E2: 3233.77 | F2: 3237.15 | G2: 3227.77 | H2: 3229.64 | I2: 4871300 | J2: 4521496000000 | K2: Row count (1.1): | L2: =ROWS(A2:A1301) -> 1300
A3: 45659 | B3: SBK | C3: Standard Bank | D3: Financials | E3: 178.01 | F3: 179.37 | G3: 177.26 | H3: 177.85 | I3: 354515 | J3: 44462500000 | K3: Unique tickers (1.2): | L3: =COUNTA(_xlfn.UNIQUE(B2:B1301)) -> 5
A4: 45659 | B4: AGL | C4: Anglo American | D4: Resources | E4: 620.43 | F4: 623.35 | G4: 616.89 | H4: 618.28 | I4: 3123559 | J4: 494624000000 | K4: Date range (1.3): | L4: 2025-01-02:2025-12-31
A5: 45659 | B5: MTN | C5: MTN Group | D5: Telecomms | E5: 120.7 | F5: 121.46 | G5: 120.13 | H5: 120.61 | I5: 3185309 | J5: 26534200000
A6: 45659 | B6: VOD | C6: Vodacom | D6: Telecomms | E6: 127.21 | F6: 128.33 | G6: 127.05 | H6: 128.3 | I6: 3475376 | J6: 25660000000 | K6: Data quality issue 1 (1.4): | L6: D53: THE CASING OF FINANCIALS DOES NOT MATCH THE OTHER ONES
A7: 45660 | B7: NPN | C7: Naspers | D7: Technology | E7: 3170.72 | F7: 3189.31 | G7: 3160.68 | H7: 3178.68 | I7: 3333614 | J7: 4450152000000 | K7: Data quality issue 2: | L7: ← your answer here
A8: 45660 | B8: SBK | C8: Standard Bank | D8: Financials | E8: 174.2 | F8: 175.22 | G8: 173.24 | H8: 173.81 | I8: 969343 | J8: 43452500000 | K8: Data quality issue 3: | L8: ← your answer here
A9: 45660 | B9: AGL | C9: Anglo American | D9: Resources | E9: 620.3 | F9: 626.42 | G9: 612.44 | H9: 617.75 | I9: 4103481 | J9: 494200000000 | K9: Data quality issue 4: | L9: ← your answer here
A10: 45660 | B10: MTN | C10: MTN Group | D10: Telecomms | E10: 119.5 | F10: 120.19 | G10: 119.05 | H10: 119.35 | I10: 898967 | J10: 26257000000 | K10: Data quality issue 5: | L10: ← your answer here
A11: 45660 | B11: VOD | C11: Vodacom | D11: Telecomms | E11: 129.29 | F11: 129.78 | G11: 128.89 | H11: 129.54 | I11: 1670719 | J11: 25908000000
A12: 45663 | B12: NPN | C12: Naspers | D12: Technology | E12: 3142.55 | F12: 3147.23 | G12: 3108.31 | H12: 3116.86 | I12: 3020280 | J12: 4363604000000
A13: 45663 | B13: SBK | C13: Standard Bank | D13: Financials | E13: 172.05 | F13: 173.36 | G13: 170.06 | H13: 170.82 | I13: 569276 | J13: 42705000000
A14: 45663 | B14: AGL | C14: Anglo American | D14: Resources | E14: 621.05 | F14: 625.78 | G14: 611 | H14: 619.38 | I14: 2939709 | J14: 495504000000
A15: 45663 | B15: MTN | C15: MTN Group | D15: Telecomms | E15: 120.97 | F15: 121.23 | G15: 119.86 | H15: 121.07 | I15: 4149128 | J15: 26635400000
A16: 45663 | B16: VOD | C16: Vodacom | D16: Telecomms | E16: 130.23 | F16: 130.68 | G16: 130.19 | H16: 130.56 | I16: 3893963 | J16: 26112000000
A17: 45664 | B17: NPN | C17: Naspers | D17: Technology | E17: 3059.33 | F17: 3079.12 | G17: 3044.53 | H17: 3052.12 | I17: 1460410 | J17: 4272968000000
A18: 45664 | B18: SBK | C18: Standard Bank | D18: Financials | E18: 169.74 | F18: 169.78 | G18: 169.11 | H18: 169.53 | I18: 3841334 | J18: 42382500000
A19: 45664 | B19: AGL | C19: Anglo American | D19: Resources | E19: 620.81 | F19: 624.83 | G19: 618.02 | H19: 622.08 | I19: 4226287 | J19: 497664000000
A20: 45664 | B20: MTN | C20: MTN Group | D20: Telecomms | E20: 116.34 | F20: 116.79 | G20: 116.25 | H20: 116.64 | I20: 4804433 | J20: 25660800000
A21: 45664 | B21: VOD | C21: Vodacom | D21: Telecomms | E21: 130.36 | F21: 130.37 | G21: 128.58 | H21: 129.19 | I21: 2762057 | J21: 25838000000
A22: 45665 | B22: NPN | C22: Naspers | D22: Technology | E22: 3006.56 | F22: 3017.1 | G22: 2959.48 | H22: 2974.66 | I22: 4499220 | J22: 4164524000000
... A502: 45799 | B502: NPN | C502: Naspers | D502: Technology | E502: 3821.34 | F502: 3855.87 | G502: 3821.12 | H502: 3855.85 | I502: 4072628 | J502: 5398190000000
A503: 45799 | B503: SBK | C503: Standard Bank | D503: Financials | E503: 167.41 | F503: 167.62 | G503: 164.75 | H503: '165 | I503: 1284705 | J503: 41250000000
A504: 45799 | B504: AGL | C504: Anglo American | D504: Resources | E504: 564.15 | F504: 571.3 | G504: 560.8 | H504: 567.21 | I504: 3891725 | J504: 453768000000
A505: 45799 | B505: MTN | C505: MTN Group | D505: Telecomms | E505: 104.88 | F505: 105.11 | G505: 104.48 | H505: 104.61 | I505: 2035961 | J505: 23014200000
A506: 45799 | B506: VOD | C506: Vodacom | D506: Telecomms | E506: 145.59 | F506: 147.01 | G506: 144.05 | H506: 144.55 | I506: 2754797 | J506: 28910000000
A507: 45800 | B507: NPN | C507: Naspers | D507: Technology | E507: 3840.92 | F507: 3846.85 | G507: 3817.42 | H507: 3842.67 | I507: 1098806 | J507: 5379738000000
A508: 45800 | B508: SBK | C508: Standard Bank | D508: Financials | E508: 167.75 | F508: 169.43 | G508: 167.35 | H508: 167.93 | I508: 1364415 | J508: 41982500000
A509: 45800 | B509: AGL | C509: Anglo American | D509: Resources | E509: 568.89 | F509: 569.62 | G509: 566.57 | H509: 567.02 | I509: 3001943 | J509: 453616000000
A510: 45800 | B510: MTN | C510: MTN Group | D510: Telecomms | E510: 105.89 | F510: 107.15 | G510: 105.45 | H510: 106.43 | I510: 2554162 | J510: 23414600000
A511: 45800 | B511: VOD | C511: Vodacom | D511: Telecomms | E511: 142.33 | F511: 143.1 | G511: 141.54 | H511: 141.66 | I511: 1080935 | J511: 28332000000
A512: 45803 | B512: NPN | C512: Naspers | D512: Technology | E512: 3764.82 | F512: 3793.56 | G512: 3743.81 | H512: 3766.43 | I512: 4394013 | J512: 5273002000000
A513: 45803 | B513: SBK | C513: Standard Bank | D513: Financials | E513: 163.11 | F513: 163.15 | G513: 163.03 | H513: 163.12 | I513: 1081328 | J513: 40780000000
A514: 45803 | B514: AGL | C514: Anglo American | D514: Resources | E514: 566.01 | F514: 570.99 | G514: 563.82 | H514: 564.27 | I514: 4783077 | J514: 451416000000
A515: 45803 | B515: MTN | C515: MTN Group | D515: Telecomms | E515: 105.16 | F515: 106.93 | G515: 103.84 | H515: 106.39 | I515: 4449969 | J515: 23405800000
... A1117: 45972 | B1117: NPN | C1117: Naspers | D1117: Technology | E1117: 4228.04 | F1117: 4273.78 | G1117: 4200.05 | H1117: 4207.67 | I1117: 911693 | J1117: 5890738000000
A1118: 11/11/2025 | B1118: SBK | C1118: Standard Bank | D1118: Financials | E1118: 135.35 | F1118: 136.1 | G1118: 135.31 | H1118: 135.7 | I1118: 307278 | J1118: 33925000000
A1119: 45972 | B1119: AGL | C1119: Anglo American | D1119: Resources | E1119: 625 | F1119: 627.01 | G1119: 621.62 | H1119: 625.39 | I1119: 3582717 | J1119: 500312000000
A1120: 45972 | B1120: MTN | C1120: MTN Group | D1120: Telecomms | E1120: 104.21 | F1120: 104.66 | G1120: 103.31 | H1120: 103.9 | I1120: 888038 | J1120: 22858000000
...

Sheet 2_Enriched
A1: Date | B1: Ticker | C1: Company | D1: Sector | E1: Open (R) | F1: High (R) | G1: Low (R) | H1: Close (R) | I1: Volume | J1: Mkt Cap (R) | K1: Daily Return % | L1: Price Range | M1: Range % | N1: Vol Flag | O1: Mkt Cap Bn | P1: Month | Q1: Quarter | R1: ← Add your formulas in columns K through Q
A2: 45659 | B2: NPN | C2: Naspers | D2: Technology | E2: 3193.72 | F2: 3198.14 | G2: 3190.88 | H2: 3196.23 | I2: 4874866 | J2: 4474722000000 | K2: =((H2-E2)/E2)*100 -> 0.078591736 | L2: =F2-G2 -> 7.26 | M2: =L2/E2 -> 0.0022732112 | N2: =IF(I2>2000000,"High volume","Normal") -> High volume | O2: =J2/1000000000 -> 4474.722 | P2: =MONTH(A2) -> 1 | Q2: {=_xlfn.IFS(P2<=3,"Q1",P2<=6,"Q2",P2<=9,"Q3",P2<=12,"Q4")} -> Q1
A3: 45659 | B3: SBK | C3: Standard Bank | D3: Financials | E3: 179.91 | F3: 181.2 | G3: 179.13 | H3: 179.19 | I3: 2134068 | J3: 44797500000 | K3: =((H3-E3)/E3)*100 -> -0.4002001 | L3: =F3-G3 -> 2.07 | M3: =L3/E3 -> 0.011505753 | N3: =IF(I3>2000000,"High volume","Normal") -> High volume | O3: =J3/1000000000 -> 44.7975 | P3: =MONTH(A3) -> 1 | Q3: {=_xlfn.IFS(P3<=3,"Q1",P3<=6,"Q2",P3<=9,"Q3",P3<=12,"Q4")} -> Q1
A4: 45659 | B4: AGL | C4: Anglo American | D4: Resources | E4: 621.5 | F4: 628.21 | G4: 614.19 | H4: 624.02 | I4: 3819187 | J4: 499216000000 | K4: =((H4-E4)/E4)*100 -> 0.40547064 | L4: =F4-G4 -> 14.02 | M4: =L4/E4 -> 0.022558327 | N4: =IF(I4>2000000,"High volume","Normal") -> High volume | O4: =J4/1000000000 -> 499.216 | P4: =MONTH(A4) -> 1 | Q4: {=_xlfn.IFS(P4<=3,"Q1",P4<=6,"Q2",P4<=9,"Q3",P4<=12,"Q4")} -> Q1
A5: 45659 | B5: MTN | C5: MTN Group | D5: Telecomms | E5: 118.95 | F5: 119.18 | G5: 117.7 | H5: 118.9 | I5: 354515 | J5: 26158000000 | K5: =((H5-E5)/E5)*100 -> -0.042034468 | L5: =F5-G5 -> 1.48 | M5: =L5/E5 -> 0.012442203 | N5: =IF(I5>2000000,"High volume","Normal") -> Normal | O5: =J5/1000000000 -> 26.158 | P5: =MONTH(A5) -> 1 | Q5: {=_xlfn.IFS(P5<=3,"Q1",P5<=6,"Q2",P5<=9,"Q3",P5<=12,"Q4")} -> Q1
A6: 45659 | B6: VOD | C6: Vodacom | D6: Telecomms | E6: 130.09 | F6: 130.7 | G6: 129.35 | H6: 129.64 | I6: 3123559 | J6: 25928000000 | K6: =((H6-E6)/E6)*100 -> -0.34591437 | L6: =F6-G6 -> 1.35 | M6: =L6/E6 -> 0.010377431 | N6: =IF(I6>2000000,"High volume","Normal") -> High volume | O6: =J6/1000000000 -> 25.928 | P6: =MONTH(A6) -> 1 | Q6: {=_xlfn.IFS(P6<=3,"Q1",P6<=6,"Q2",P6<=9,"Q3",P6<=12,"Q4")} -> Q1
A7: 45660 | B7: NPN | C7: Naspers | D7: Technology | E7: 3214.95 | F7: 3235.09 | G7: 3199.89 | H7: 3212.53 | I7: 3185309 | J7: 4497542000000 | K7: =((H7-E7)/E7)*100 -> -0.075273332 | L7: =F7-G7 -> 35.2 | M7: =L7/E7 -> 0.010948848 | N7: =IF(I7>2000000,"High volume","Normal") -> High volume | O7: =J7/1000000000 -> 4497.542 | P7: =MONTH(A7) -> 1 | Q7: {=_xlfn.IFS(P7<=3,"Q1",P7<=6,"Q2",P7<=9,"Q3",P7<=12,"Q4")} -> Q1
A8: 45660 | B8: SBK | C8: Standard Bank | D8: Financials | E8: 175.35 | F8: 176.89 | G8: 175.13 | H8: 176.84 | I8: 3475376 | J8: 44210000000 | K8: =((H8-E8)/E8)*100 -> 0.84972911 | L8: =F8-G8 -> 1.76 | M8: =L8/E8 -> 0.010037069 | N8: =IF(I8>2000000,"High volume","Normal") -> High volume | O8: =J8/1000000000 -> 44.21 | P8: =MONTH(A8) -> 1 | Q8: {=_xlfn.IFS(P8<=3,"Q1",P8<=6,"Q2",P8<=9,"Q3",P8<=12,"Q4")} -> Q1
A9: 45660 | B9: AGL | C9: Anglo American | D9: Resources | E9: 612.64 | F9: 616.23 | G9: 610.7 | H9: 614.18 | I9: 3333614 | J9: 491344000000 | K9: =((H9-E9)/E9)*100 -> 0.25137112 | L9: =F9-G9 -> 5.53 | M9: =L9/E9 -> 0.0090265082 | N9: =IF(I9>2000000,"High volume","Normal") -> High volume | O9: =J9/1000000000 -> 491.344 | P9: =MONTH(A9) -> 1 | Q9: {=_xlfn.IFS(P9<=3,"Q1",P9<=6,"Q2",P9<=9,"Q3",P9<=12,"Q4")} -> Q1
A10: 45660 | B10: MTN | C10: MTN Group | D10: Telecomms | E10: 116.46 | F10: 117.14 | G10: 115.82 | H10: 116.2 | I10: 969343 | J10: 25564000000 | K10: =((H10-E10)/E10)*100 -> -0.22325262 | L10: =F10-G10 -> 1.32 | M10: =L10/E10 -> 0.011334364 | N10: =IF(I10>2000000,"High volume","Normal") -> Normal | O10: =J10/1000000000 -> 25.564 | P10: =MONTH(A10) -> 1 | Q10: {=_xlfn.IFS(P10<=3,"Q1",P10<=6,"Q2",P10<=9,"Q3",P10<=12,"Q4")} -> Q1
A11: 45660 | B11: VOD | C11: Vodacom | D11: Telecomms | E11: 130.06 | F11: 131.34 | G11: 128.41 | H11: 129.52 | I11: 4103481 | J11: 25904000000 | K11: =((H11-E11)/E11)*100 -> -0.41519299 | L11: =F11-G11 -> 2.93 | M11: =L11/E11 -> 0.022528064 | N11: =IF(I11>2000000,"High volume","Normal") -> High volume | O11: =J11/1000000000 -> 25.904 | P11: =MONTH(A11) -> 1 | Q11: {=_xlfn.IFS(P11<=3,"Q1",P11<=6,"Q2",P11<=9,"Q3",P11<=12,"Q4")} -> Q1
A12: 45663 | B12: NPN | C12: Naspers | D12: Technology | E12: 3182.96 | F12: 3201.23 | G12: 3170.99 | H12: 3179.06 | I12: 898967 | J12: 4450684000000 | K12: =((H12-E12)/E12)*100 -> -0.12252746 | L12: =F12-G12 -> 30.24 | M12: =L12/E12 -> 0.0095005906 | N12: =IF(I12>2000000,"High volume","Normal") -> Normal | O12: =J12/1000000000 -> 4450.684 | P12: =MONTH(A12) -> 1 | Q12: {=_xlfn.IFS(P12<=3,"Q1",P12<=6,"Q2",P12<=9,"Q3",P12<=12,"Q4")} -> Q1
A13: 45663 | B13: SBK | C13: Standard Bank | D13: Financials | E13: 178.2 | F13: 178.88 | G13: 177.65 | H13: 178.55 | I13: 1670719 | J13: 44637500000 | K13: =((H13-E13)/E13)*100 -> 0.19640853 | L13: =F13-G13 -> 1.23 | M13: =L13/E13 -> 0.0069023569 | N13: =IF(I13>2000000,"High volume","Normal") -> Normal | O13: =J13/1000000000 -> 44.6375 | P13: =MONTH(A13) -> 1 | Q13: {=_xlfn.IFS(P13<=3,"Q1",P13<=6,"Q2",P13<=9,"Q3",P13<=12,"Q4")} -> Q1
... A1301: 46022 | B1301: VOD | C1301: Vodacom | D1301: Telecomms | E1301: 141.79 | F1301: 142.16 | G1301: 140.91 | H1301: 140.99 | I1301: 3714220 | J1301: 28198000000 | K1301: =((H1301-E1301)/E1301)*100 -> -0.56421468 | L1301: =F1301-G1301 -> 1.25 | M1301: =L1301/E1301 -> 0.0088158544 | N1301: =IF(I1301>2000000,"High volume","Normal") -> High volume | O1301: =J1301/1000000000 -> 28.198 | P1301: =MONTH(A1301) -> 12 | Q1301: {=_xlfn.IFS(P1301<=3,"Q1",P1301<=6,"Q2",P1301<=9,"Q3",P1301<=12,"Q4")} -> Q4

Sheet Sheet1
A1: TICKER | B1: AVERAGES FOR EACH TICKER
A2: NPN | B2: =AVERAGEIFS('2_Enriched'!H2:H1301,'2_Enriched'!B2:B1301,"NPN") -> 2515.1033
A3: VOD | B3: =AVERAGEIFS('2_Enriched'!H3:H1302,'2_Enriched'!B3:B1302,"VOD") -> 141.13562
A4: MTN | B4: =AVERAGEIFS('2_Enriched'!H4:H1303,'2_Enriched'!B4:B1303,"MTN") -> 93.369654
A5: AGL | B5: =AVERAGEIFS('2_Enriched'!H5:H1304,'2_Enriched'!B5:B1304,"AGL") -> 610.48749
A6: SBK | B6: =AVERAGEIFS('2_Enriched'!H6:H1305,'2_Enriched'!B6:B1305,"SBK") -> 214.65375

Sheet 3_Summary
B1: Module 1 — Summary Analysis
B2: Use SUMIFS, COUNTIFS, and AVERAGEIFS referencing sheet 2_Enriched. Enter your formulas in the yellow cells.
B4: Task 3 — Aggregate Formulas [20 marks] | C4: Your Formula / Answer
B5: 3.1 Total trading volume — NPN (Naspers)
B6: 3.2 Total trading volume — SBK (Standard Bank)
B7: 3.3 Average closing price — AGL in Q1 (Jan–Mar 2025)
B8: 3.4 Days MTN had Daily Return % > 1%
B9: 3.5 Days any stock: High Volume AND negative daily return
B10: 3.6 Total Mkt Cap (Bn) — Technology sector

Sheet 4_Analysis
A1: Task 4 — Pivot Tables & Charts
A2: 4.1 Click any cell below row 5. Insert → PivotTable → use 2_Enriched as the data source.
A3: Rows: Ticker | Columns: Month | Values: Average of Close (R)
A4: 4.2 Below the first pivot table, add a second PivotTable.
A5: Rows: Sector | Columns: Quarter | Values: Sum of Volume
A6: 4.3 From Pivot Table 1: Insert a Line Chart. Title: 'JSE Average Closing Price by Month'.
A7: Label both axes. Use distinct colours per ticker.
A8: 4.4 From Pivot Table 2: Insert a Stacked Bar Chart. Title: 'Volume by Sector per Quarter'.

Sheet 5_TradeEntry
A1: Trade Order Entry Form
A2: Task 5: Apply data validation to columns B–E as instructed in sheet 0_Instructions.
A3: # | B3: Ticker | C3: Trade Type | D3: Quantity | E3: Price (R) | F3: Trade Date | G3: Notes
A4: 1
A5: 2
A6: 3
A7: 4
A8: 5
A9: 6
A10: 7
A11: 8
A12: 9
A13: 10
A14: 11
A15: 12
... A23: 20

Sheet 6_Capstone
A1: Task 6 — Capstone Formula Challenge
A2: Enter single formulas in the yellow cells below. All answers should reference 2_Enriched.
A4: 6.1 Highest average closing price across ALL 5 stocks (full year) | B4: =MAX(Sheet1!B2,Sheet1!B3,Table1[[#This Row],[AVERAGES FOR EACH TICKER]],Sheet1!B5,Sheet1!B6) -> 2515.1033
A5: 6.2 Ticker with the HIGHEST average closing price | B5: {=_xlfn.IFS('6_Capstone'!B4 = Sheet1!B2,"NPN",'6_Capstone'!B4 = Sheet1!B3,"VOD",'6_Capstone'!B4 = Sheet1!B4,"MTN",'6_Capstone'!B4 = Sheet1!B5,"AGL")} -> NPN
A6: 6.3 NPN Sharpe-inspired ratio = AVG(daily return%) / STDEV(daily return%) | B6: =AVERAGEIF('2_Enriched'!B2:B1301,"NPN",'2_Enriched'!K2:K1301)/STDEV('2_Enriched'!K2:K1301) -> -0.012231156
A7: 6.4 3rd highest single-day closing price across ALL stocks | B7: =LARGE('2_Enriched'!H2:H1305,3) -> 3260.95
